<?xml version="1.0" encoding="UTF-8"?>
<testng-results skipped="0" failed="2" ignored="0" total="2" passed="0">
  <reporter-output>
  </reporter-output>
  <suite name="Default suite" duration-ms="101" started-at="2019-04-18T10:25:08Z" finished-at="2019-04-18T10:25:08Z">
    <groups>
    </groups>
    <test name="Default test" duration-ms="101" started-at="2019-04-18T10:25:08Z" finished-at="2019-04-18T10:25:08Z">
      <class name="com.jbk.LoginTest1">
        <test-method status="FAIL" signature="aaLogintestcase1()[pri:0, instance:com.jbk.LoginTest1@197c004]" name="aaLogintestcase1" duration-ms="27" started-at="2019-04-18T15:55:08Z" finished-at="2019-04-18T15:55:08Z">
          <exception class="java.lang.AssertionError">
            <message>
              <![CDATA[expected [4] but found [3]]]>
            </message>
            <full-stacktrace>
              <![CDATA[java.lang.AssertionError: expected [4] but found [3]
	at org.testng.Assert.fail(Assert.java:93)
	at org.testng.Assert.failNotEquals(Assert.java:512)
	at org.testng.Assert.assertEqualsImpl(Assert.java:134)
	at org.testng.Assert.assertEquals(Assert.java:115)
	at org.testng.Assert.assertEquals(Assert.java:388)
	at org.testng.Assert.assertEquals(Assert.java:398)
	at com.jbk.LoginTest1.aaLogintestcase1(LoginTest1.java:13)
	at sun.reflect.NativeMethodAccessorImpl.invoke0(Native Method)
	at sun.reflect.NativeMethodAccessorImpl.invoke(Unknown Source)
	at sun.reflect.DelegatingMethodAccessorImpl.invoke(Unknown Source)
	at java.lang.reflect.Method.invoke(Unknown Source)
	at org.testng.internal.MethodInvocationHelper.invokeMethod(MethodInvocationHelper.java:108)
	at org.testng.internal.Invoker.invokeMethod(Invoker.java:661)
	at org.testng.internal.Invoker.invokeTestMethod(Invoker.java:869)
	at org.testng.internal.Invoker.invokeTestMethods(Invoker.java:1193)
	at org.testng.internal.TestMethodWorker.invokeTestMethods(TestMethodWorker.java:126)
	at org.testng.internal.TestMethodWorker.run(TestMethodWorker.java:109)
	at org.testng.TestRunner.privateRun(TestRunner.java:744)
	at org.testng.TestRunner.run(TestRunner.java:602)
	at org.testng.SuiteRunner.runTest(SuiteRunner.java:380)
	at org.testng.SuiteRunner.runSequentially(SuiteRunner.java:375)
	at org.testng.SuiteRunner.privateRun(SuiteRunner.java:340)
	at org.testng.SuiteRunner.run(SuiteRunner.java:289)
	at org.testng.SuiteRunnerWorker.runSuite(SuiteRunnerWorker.java:52)
	at org.testng.SuiteRunnerWorker.run(SuiteRunnerWorker.java:86)
	at org.testng.TestNG.runSuitesSequentially(TestNG.java:1301)
	at org.testng.TestNG.runSuitesLocally(TestNG.java:1226)
	at org.testng.TestNG.runSuites(TestNG.java:1144)
	at org.testng.TestNG.run(TestNG.java:1115)
	at org.testng.remote.AbstractRemoteTestNG.run(AbstractRemoteTestNG.java:132)
	at org.testng.remote.RemoteTestNG.initAndRun(RemoteTestNG.java:230)
	at org.testng.remote.RemoteTestNG.main(RemoteTestNG.java:76)
]]>
            </full-stacktrace>
          </exception> <!-- java.lang.AssertionError -->
          <reporter-output>
          </reporter-output>
        </test-method> <!-- aaLogintestcase1 -->
        <test-method status="FAIL" signature="aaaLogintestcase2()[pri:1, instance:com.jbk.LoginTest1@197c004]" name="aaaLogintestcase2" duration-ms="4" started-at="2019-04-18T15:55:08Z" finished-at="2019-04-18T15:55:08Z">
          <exception class="java.lang.AssertionError">
            <message>
              <![CDATA[expected [4] but found [3]]]>
            </message>
            <full-stacktrace>
              <![CDATA[java.lang.AssertionError: expected [4] but found [3]
	at org.testng.Assert.fail(Assert.java:93)
	at org.testng.Assert.failNotEquals(Assert.java:512)
	at org.testng.Assert.assertEqualsImpl(Assert.java:134)
	at org.testng.Assert.assertEquals(Assert.java:115)
	at org.testng.Assert.assertEquals(Assert.java:388)
	at org.testng.Assert.assertEquals(Assert.java:398)
	at com.jbk.LoginTest1.aaaLogintestcase2(LoginTest1.java:27)
	at sun.reflect.NativeMethodAccessorImpl.invoke0(Native Method)
	at sun.reflect.NativeMethodAccessorImpl.invoke(Unknown Source)
	at sun.reflect.DelegatingMethodAccessorImpl.invoke(Unknown Source)
	at java.lang.reflect.Method.invoke(Unknown Source)
	at org.testng.internal.MethodInvocationHelper.invokeMethod(MethodInvocationHelper.java:108)
	at org.testng.internal.Invoker.invokeMethod(Invoker.java:661)
	at org.testng.internal.Invoker.invokeTestMethod(Invoker.java:869)
	at org.testng.internal.Invoker.invokeTestMethods(Invoker.java:1193)
	at org.testng.internal.TestMethodWorker.invokeTestMethods(TestMethodWorker.java:126)
	at org.testng.internal.TestMethodWorker.run(TestMethodWorker.java:109)
	at org.testng.TestRunner.privateRun(TestRunner.java:744)
	at org.testng.TestRunner.run(TestRunner.java:602)
	at org.testng.SuiteRunner.runTest(SuiteRunner.java:380)
	at org.testng.SuiteRunner.runSequentially(SuiteRunner.java:375)
	at org.testng.SuiteRunner.privateRun(SuiteRunner.java:340)
	at org.testng.SuiteRunner.run(SuiteRunner.java:289)
	at org.testng.SuiteRunnerWorker.runSuite(SuiteRunnerWorker.java:52)
	at org.testng.SuiteRunnerWorker.run(SuiteRunnerWorker.java:86)
	at org.testng.TestNG.runSuitesSequentially(TestNG.java:1301)
	at org.testng.TestNG.runSuitesLocally(TestNG.java:1226)
	at org.testng.TestNG.runSuites(TestNG.java:1144)
	at org.testng.TestNG.run(TestNG.java:1115)
	at org.testng.remote.AbstractRemoteTestNG.run(AbstractRemoteTestNG.java:132)
	at org.testng.remote.RemoteTestNG.initAndRun(RemoteTestNG.java:230)
	at org.testng.remote.RemoteTestNG.main(RemoteTestNG.java:76)
]]>
            </full-stacktrace>
          </exception> <!-- java.lang.AssertionError -->
          <reporter-output>
          </reporter-output>
        </test-method> <!-- aaaLogintestcase2 -->
      </class> <!-- com.jbk.LoginTest1 -->
    </test> <!-- Default test -->
  </suite> <!-- Default suite -->
</testng-results>
